Workbook

Sheet Léeme
A1: Modelo financiero – FieldOps IA (Austral Conecta S.A., empresa ficticia)
A2: Plan Maestro CAIO a 12 meses · Versión alineada a los Anexos A–I (fuente mandatoria de cifras) · 24/10/2026
A4: Propósito | B4: Sustentar el caso de negocio de la presentación al board (slides 1, 3, 4, 5, 8, 9 y 10) y el anexo B. Todas las cifras coinciden con los Anexos A–I.
A5: Moneda | B5: USD constantes. Montos en USD millones (USD M) salvo que el encabezado diga otra cosa. Flujos antes de impuestos salvo aclaración.
A6: Premisa de personas | B6: Sin despidos de planta propia: los 400 técnicos propios mantienen 7 visitas por día. Todo el ahorro cae en el volumen facturado por terceros (contratistas de campo).
A8: Hojas
A9: Supuestos | B9: Todos los datos de entrada, con su origen. Es la única hoja que se edita.
A10: Línea base | B10: Dotación, visitas, costo de campo, pérdida actual (USD 25,6 M/año), métrica norte y RPU de partida.
A11: Beneficios | B11: Las 5 palancas a régimen separadas en ahorro e ingreso, puente bruto → neto y beneficio bruto planificado por trimestre.
A12: Inversión | B12: Inversión 2027 por trimestre, componente, contingencia y tramo; opex de la IA por trimestre.
A13: Flujo y ROI | B13: Estimación trimestral incremental contra la línea base: visitas y técnicos de terceros, factura de terceros, ahorro, ingreso, flujo, ROI acumulado y payback.
A14: Proyección 5 años | B14: Flujos 2027–2031, VAN y TIR antes y después de impuestos (flujos trimestrales descontados a mitad de período).
A15: Escenarios | B15: Pesimista, base y optimista con probabilidad, VAN, TIR, payback, gatillos y decisiones; costo de esperar.
A16: Sensibilidad | B16: Impacto de los supuestos clave sobre neto a régimen, neto a 24 meses y VAN.
A17: KPIs | B17: Métrica norte, guardas y KPIs operativos: línea base vs. meta a régimen; gate de Q2.
A19: Convención de colores | B19: Texto azul = dato de entrada editable · Texto negro = fórmula · Texto verde = vínculo a otra hoja · Fondo amarillo = supuesto clave.
A20: Horizonte | B20: Q1–Q4 2027 = plan de 12 meses. 2028 = primer año a régimen. 2029–2031 = proyección para VAN y TIR.

Sheet Supuestos
A1: Supuestos del modelo
A2: Única hoja de entrada. Texto azul = editable; amarillo = supuesto clave.
A3: Supuesto | B3: Valor | C3: Unidad | D3: Origen | E3: Comentario
A4: 1. Dotación y operación de campo
A5: Técnicos totales | B5: 1500 | C5: técnicos | D5: Definición del caso
A6: Técnicos que hacen visitas a domicilio | B6: 1000 | C6: técnicos | D6: Anexo B | E6: El resto (500) hace red, mantenimiento y supervisión; de ahí salen los curadores.
A7: Técnicos de domicilio de planta propia | B7: 400 | C7: técnicos | D7: Anexo B | E7: Capacidad fija: no se reduce (sin despidos).
A8: Técnicos de domicilio de terceros (contratistas) | B8: =B6-B7 -> 600 | C8: técnicos | D8: Fórmula | E8: Volumen variable: acá cae todo el ahorro.
A9: Visitas por técnico y día (tope país) | B9: 7 | C9: visitas/día | D9: Definición del caso | E9: Dato de la operación.
A10: Días hábiles por año | B10: 255 | C10: días | D10: Anexo B
A11: Visitas anuales (base 2026) | B11: 1784000 | C11: visitas | D11: Anexo B | E11: ≈ 1.000 técnicos × 7 × 255 = 1,785 M; se usa el registro del FSM.
A12: Órdenes resueltas por año (base 2026) | B12: 1205600 | C12: órdenes | D12: Anexo B | E12: 148 visitas cada 100 órdenes resueltas.
A13: Costo de campo anual (base 2026) | B13: 57 | C13: USD M | D13: Anexo B | E13: Propio + terceros.
A14: Costo por visita (propia o tercerizada) | B14: 32 | C14: USD/visita | D14: Anexo B | E14: Tarifa del contratista; costo evitable de cada visita que no se hace.
A15: Costo por caso resuelto a distancia | B15: 2.5 | C15: USD/caso | D15: Anexo B | E15: IA conversacional, consultas a la red y supervisión.
A16: Abonados | B16: 1.6 | C16: millones | D16: Definición del caso
A17: ARPU mensual | B17: 22 | C17: USD/mes | D17: Anexo B | E17: Una reparación que falla a la primera cuesta USD 59 = 2,7 meses de ARPU.
A18: Costo de una reparación que falla a la primera | B18: 59 | C18: USD | D18: Anexo B | E18: Revisita + contactos adicionales + bonificación.
A19: 2. Pérdida actual (diagnóstico)
A20: Revisitas de reparación (falla a la primera) | B20: 337600 | C20: visitas/año | D20: Anexo B
A21: Revisitas de instalación (mal hechas) | B21: 96400 | C21: visitas/año | D21: Anexo B
A22: Visitas que se podían resolver a distancia | B22: 181000 | C22: visitas/año | D22: Anexo B | E22: Muestra de cierres: reinicios, configuración, fallas de red conocidas.
A23: Visitas fallidas (cliente ausente o sin acceso) | B23: 144700 | C23: visitas/año | D23: Anexo B | E23: 8,1% de las visitas.
A24: Bonificaciones por fallas repetidas | B24: 1.3 | C24: USD M/año | D24: Anexo B | E24: Ingreso resignado.
A25: 3. Palancas a régimen (escenario base, ya neto del grupo de control)
A26: Triage: % de reclamos de reparación que atiende | B26: 0.5 | C26: % | D26: Anexo B
A27: Triage: % de los atendidos que resuelve sin visita | B27: 0.2 | C27: % | D27: Anexo B | E27: Es también la condición de volumen del gate de Q2.
A28: Órdenes resueltas sin visita | B28: =B26*B27 -> 0.1 | C28: % órdenes | D28: Fórmula | E28: Contención: 50% × 20% = 10%.
A29: Visitas fallidas: línea base (redondeo) | B29: 0.08 | C29: % visitas | D29: Anexo B
A30: Visitas fallidas: meta | B30: 0.05 | C30: % visitas | D30: Anexo B | E30: Ventana de 20 min y aviso proactivo.
A31: First-time fix: línea base | B31: 0.75 | C31: % | D31: Anexo B
A32: First-time fix: meta | B32: 0.82 | C32: % | D32: Anexo B | E32: Briefing + copiloto + foto.
A33: Revisitas de reparación evitadas (75% → 82%) | B33: 115000 | C33: visitas/año | D33: Anexo B
A34: Reducción de revisitas de instalación | B34: 0.25 | C34: % | D34: Anexo B | E34: Control de calidad por foto.
A35: Reducción de bonificaciones | B35: 0.28 | C35: % | D35: Anexo B | E35: Menos fallas repetidas.
A36: Grupo de control permanente | B36: 0.1 | C36: % reclamos | D36: Anexo E | E36: Ya descontado de los beneficios.
A37: 4. Opex recurrente de la IA a régimen (2028)
A38: Consumo de modelos | B38: 0.55 | C38: USD M/año | D38: Anexo B
A39: Nube y plataforma | B39: 0.35 | C39: USD M/año | D39: Anexo B
A40: Operación de modelos (MLOps) | B40: 0.4 | C40: USD M/año | D40: Anexo B
...

Sheet Línea base
A1: Línea base: operación actual (2026, antes de la IA)
A3: Indicador | B3: Valor | C3: Cálculo
A4: Dotación y visitas
A5: Técnicos propios de domicilio | B5: =Supuestos!$B$7 -> 400
A6: Técnicos de terceros de domicilio | B6: =Supuestos!$B$8 -> 600
A7: Visitas por año de planta propia | B7: =Supuestos!$B$7*Supuestos!$B$9*Supuestos!$B$10 -> 714000 | C7: 400 × 7 × 255
A8: Visitas por año de terceros | B8: =Supuestos!$B$11-B7 -> 1070000 | C8: Visitas totales − propias
A9: Participación de terceros en las visitas | B9: =B8/Supuestos!$B$11 -> 0.59977578
A10: Factura anual de terceros (USD M) | B10: =B8*Supuestos!$B$14/10^6 -> 34.24 | C10: Visitas de terceros × USD 32
A11: Visitas cada 100 órdenes resueltas | B11: =Supuestos!$B$11/Supuestos!$B$12*100 -> 147.97611
A12: Órdenes resueltas por técnico y día | B12: =Supuestos!$B$12/(Supuestos!$B$6*Supuestos!$B$10) -> 4.7278431
A14: Pérdida actual (USD M/año)
A15: Revisitas (reparación + instalación) | B15: =(Supuestos!$B$20+Supuestos!$B$21)*Supuestos!$B$14/10^6 -> 13.888 | C15: 434.000 × USD 32
A16: Visitas evitables (resolubles a distancia) | B16: =Supuestos!$B$22*Supuestos!$B$14/10^6 -> 5.792 | C16: 181.000 × USD 32
A17: Visitas fallidas | B17: =Supuestos!$B$23*Supuestos!$B$14/10^6 -> 4.6304 | C17: 144.700 × USD 32
A18: Bonificaciones por fallas repetidas | B18: =Supuestos!$B$24 -> 1.3
A19: Pérdida total anual | B19: =SUM(B15:B18) -> 25.6104
A20: Pérdida mensual | B20: =B19/12 -> 2.1342
A21: Pérdida como % del costo de campo | B21: =B19/Supuestos!$B$13 -> 0.44930526
A22: Revisitas totales por año | B22: =Supuestos!$B$20+Supuestos!$B$21 -> 434000
A23: Costo de las revisitas como % del costo de campo | B23: =B15/Supuestos!$B$13 -> 0.24364912
A25: Métrica norte y valor por abonado
A26: MÉTRICA NORTE: costo de campo por orden resuelta (USD) | B26: =Supuestos!$B$13*10^6/Supuestos!$B$12 -> 47.279363 | C26: Costo de campo / órdenes resueltas
A27: Costo de campo por abonado (USD/mes) | B27: =Supuestos!$B$13/Supuestos!$B$16/12 -> 2.96875
A28: Bonificaciones por abonado (USD/mes) | B28: =Supuestos!$B$24/Supuestos!$B$16/12 -> 0.067708333
A29: RPU neto de campo (USD/abonado/mes) | B29: =Supuestos!$B$17-B27-B28 -> 18.963542 | C29: ARPU − costo de campo − bonificaciones
A30: Meses de ARPU que se come una reparación fallida | B30: =Supuestos!$B$18/Supuestos!$B$17 -> 2.6818182

Sheet Beneficios
A1: Beneficios a régimen por palanca (USD M/año) y beneficio planificado por trimestre
A2: Cifras netas del grupo de control del 10%.
A3: Palanca | B3: Tipo | C3: Visitas liberadas/año | D3: USD M/año | E3: Cálculo
A4: 1 · Evitar la visita (triage remoto) | B4: Ahorro | C4: =ROUND(Supuestos!$B$12*Supuestos!$B$28,-4) -> 120000 | D4: =C4*(Supuestos!$B$14-Supuestos!$B$15)/10^6 -> 3.54 | E4: 10% de las órdenes × (USD 32 − USD 2,5 de resolución remota)
A5: 2 · Despachar bien (visitas fallidas 8% → 5%) | B5: Ahorro | C5: =ROUND(Supuestos!$B$11*(Supuestos!$B$29-Supuestos!$B$30),-2) -> 53500 | D5: =C5*Supuestos!$B$14/10^6 -> 1.712 | E5: 3 pp × 1,78 M visitas × USD 32
A6: 3 · Llegar preparado y resolver a la primera (FTF 75% → 82%) | B6: Ahorro | C6: =Supuestos!$B$33 -> 115000 | D6: =C6*Supuestos!$B$14/10^6 -> 3.68 | E6: Revisitas de reparación evitadas × USD 32
A7: 4 · Cerrar y aprender (control de calidad por foto) | B7: Ahorro | C7: =ROUND(Supuestos!$B$21*Supuestos!$B$34,-3) -> 24000 | D7: =C7*Supuestos!$B$14/10^6 -> 0.768 | E7: Revisitas de instalación −25% × USD 32
A8: 5 · Menos fallas repetidas (bonificaciones evitadas) | B8: Ingreso | D8: =Supuestos!$B$24*Supuestos!$B$35 -> 0.364 | E8: USD 1,3 M × 28%
A9: Ahorro en costo de campo (palancas 1 a 4) | C9: =SUM(C4:C7) -> 312500 | D9: =SUM(D4:D7) -> 9.7
A10: Ingreso (palanca 5) | D10: =D8 -> 0.364
A11: Beneficio bruto a régimen | C11: =C9 -> 312500 | D11: =D9+D10 -> 10.064
A12: Opex recurrente de la IA | D12: =-(Supuestos!$B$38+Supuestos!$B$39+Supuestos!$B$40) -> -1.3
A13: Beneficio neto a régimen | D13: =D11+D12 -> 8.764
A15: Ahorro como % del costo de campo | D15: =D9/Supuestos!$B$13 -> 0.17017544
A16: Captura bruta de la pérdida actual | D16: =D11/'Línea base'!$B$19 -> 0.39296536
A17: Captura neta de la pérdida actual | D17: =D13/'Línea base'!$B$19 -> 0.34220473
A18: Métrica norte a régimen (USD por orden resuelta) | D18: =(Supuestos!$B$13-D9-D12)*10^6/Supuestos!$B$12 -> 40.311878
A19: Variación de la métrica norte | D19: =D18/'Línea base'!$B$26-1 -> -0.14736842
A20: RPU neto de campo a régimen (USD/abonado/mes) | D20: ='Línea base'!$B$29+D13/Supuestos!$B$16/12 -> 19.42
A21: Técnicos de terceros equivalentes liberados | D21: =C11/(Supuestos!$B$9*Supuestos!$B$10) -> 175.07003
A22: Reducción de la factura de terceros | D22: =C11*Supuestos!$B$14/10^6/'Línea base'!$B$10 -> 0.29205607
A23: Nota: la baja del papeleo (60 → 35 min/día) no se cuenta como beneficio: es tiempo, no factura.
A25: Beneficio bruto planificado por trimestre (USD M) · dato de entrada del roadmap (anexo G)
A26: Concepto | B26: Q1 2027 | C26: Q2 2027 | D26: Q3 2027 | E26: Q4 2027 | F26: Q1 2028 | G26: Q2 2028 | H26: Q3 2028 | I26: Q4 2028
A27: Beneficio bruto del trimestre | B27: 0.1 | C27: 0.6 | D27: 1.5 | E27: 2.2 | F27: =$D$11/4 -> 2.516 | G27: =$D$11/4 -> 2.516 | H27: =$D$11/4 -> 2.516 | I27: =$D$11/4 -> 2.516
A28: Rampa: % del régimen trimestral | B28: =B27/($D$11/4) -> 0.039745628 | C28: =C27/($D$11/4) -> 0.23847377 | D28: =D27/($D$11/4) -> 0.59618442 | E28: =E27/($D$11/4) -> 0.87440382 | F28: =F27/($D$11/4) -> 1 | G28: =G27/($D$11/4) -> 1 | H28: =H27/($D$11/4) -> 1 | I28: =I27/($D$11/4) -> 1
A29: Rampa: Q1 aviso proactivo; Q2 triage en producción; Q3 copiloto y foto en todas las zonas; Q4 despacho en toda la operación.

Sheet Inversión
A1: Inversión 2027 por trimestre y tramo, y opex de la IA (USD M)
A3: Componente | B3: Q1 2027 | C3: Q2 2027 | D3: Q3 2027 | E3: Q4 2027 | F3: Total
A4: Datos e integración | B4: 0.48 | C4: 0.42 | D4: 0 | E4: 0 | F4: =SUM(B4:E4) -> 0.9
A5: Aviso proactivo | B5: 0.15 | C5: 0 | D5: 0 | E5: 0 | F5: =SUM(B5:E5) -> 0.15
A6: Triage remoto | B6: 0.15 | C6: 0.3 | D6: 0 | E6: 0 | F6: =SUM(B6:E6) -> 0.45
A7: Copiloto y visión por foto | B7: 0 | C7: 0.36 | D7: 0 | E7: 0 | F7: =SUM(B7:E7) -> 0.36
A8: Despacho inteligente y ruteo | B8: 0 | C8: 0.15 | D8: 0.25 | E8: 0 | F8: =SUM(B8:E8) -> 0.4
A9: Copiloto en todas las zonas | B9: 0 | C9: 0 | D9: 0.24 | E9: 0 | F9: =SUM(B9:E9) -> 0.24
A10: Datos y triage (escalado) | B10: 0 | C10: 0 | D10: 0.27 | E10: 0 | F10: =SUM(B10:E10) -> 0.27
A11: Cierre de componentes | B11: 0 | C11: 0 | D11: 0 | E11: 0.4 | F11: =SUM(B11:E11) -> 0.4
A12: Gobierno, equipo, dictado, capacitación y cambio | B12: 0.4 | C12: 0.46 | D12: 0.36 | E12: 0.32 | F12: =SUM(B12:E12) -> 1.54
A13: Subtotal componentes | B13: =SUM(B4:B12) -> 1.18 | C13: =SUM(C4:C12) -> 1.69 | D13: =SUM(D4:D12) -> 1.12 | E13: =SUM(E4:E12) -> 0.72 | F13: =SUM(B13:E13) -> 4.71
A14: Contingencia asignada (≈15%) | B14: 0.17 | C14: 0.25 | D14: 0.17 | E14: 0.1 | F14: =SUM(B14:E14) -> 0.69
A15: Inversión total del trimestre | B15: =B13+B14 -> 1.35 | C15: =C13+C14 -> 1.94 | D15: =D13+D14 -> 1.29 | E15: =E13+E14 -> 0.82 | F15: =SUM(B15:E15) -> 5.4
A16: Contingencia / componentes | B16: =B14/B13 -> 0.1440678 | C16: =C14/C13 -> 0.14792899 | D16: =D14/D13 -> 0.15178571 | E16: =E14/E13 -> 0.13888889 | F16: =F14/F13 -> 0.14649682
A17: Tramo | B17: Tramo 1 | C17: Tramo 1 | D17: Tramo 2 | E17: Tramo 2
A19: Tramo 1 (Q1 + Q2): se aprueba hoy | B19: =B15+C15 -> 3.29
A20: Tramo 2 (Q3 + Q4): atado al gate de Q2 | B20: =D15+E15 -> 2.11
A22: Inversión por tipo de gasto (USD M)
A23: Tecnología y plataforma | B23: 2
A24: Datos | B24: 1.4
A25: Talento y equipo | B25: 1.3
A26: Capacitación y cambio | B26: 0.7
A27: Total (control contra la inversión total) | B27: =SUM(B23:B26) -> 5.4 | C27: =IF(ROUND(B27-F15,2)=0,"OK","Revisar") -> OK
A29: Opex recurrente de la IA por trimestre (USD M)
A30: Concepto | B30: Q1 2027 | C30: Q2 2027 | D30: Q3 2027 | E30: Q4 2027 | F30: Total 2027
A31: Opex de la IA (consumo de modelos, nube, MLOps) | B31: 0.1 | C31: 0.2 | D31: 0.22 | E31: 0.28 | F31: =SUM(B31:E31) -> 0.8
A32: Lo no usado de la contingencia vuelve al CFO; la administra el comité de IA.

Sheet Flujo y ROI
A1: Estimación trimestral incremental contra la línea base (congelada en dic-2026)
A2: Cada visita que la IA evita es una visita menos facturada por terceros. La planta propia mantiene 7 visitas por día.
A3: Indicador | B3: Línea base (Q) | C3: Q1 2027 | D3: Q2 2027 | E3: Q3 2027 | F3: Q4 2027 | G3: Q1 2028 | H3: Q2 2028 | I3: Q3 2028 | J3: Q4 2028 | K3: Total 24 meses
A4: Operativo
A5: Visitas liberadas | C5: =Beneficios!$B$28*Beneficios!$C$11/4 -> 3105.1272 | D5: =Beneficios!$C$28*Beneficios!$C$11/4 -> 18630.763 | E5: =Beneficios!$D$28*Beneficios!$C$11/4 -> 46576.908 | F5: =Beneficios!$E$28*Beneficios!$C$11/4 -> 68312.798 | G5: =Beneficios!$F$28*Beneficios!$C$11/4 -> 78125 | H5: =Beneficios!$G$28*Beneficios!$C$11/4 -> 78125 | I5: =Beneficios!$H$28*Beneficios!$C$11/4 -> 78125 | J5: =Beneficios!$I$28*Beneficios!$C$11/4 -> 78125 | K5: =SUM(C5:J5) -> 449125.6
A6: Visitas totales | B6: =Supuestos!$B$11/4 -> 446000 | C6: =$B6-C5 -> 442894.87 | D6: =$B6-D5 -> 427369.24 | E6: =$B6-E5 -> 399423.09 | F6: =$B6-F5 -> 377687.2 | G6: =$B6-G5 -> 367875 | H6: =$B6-H5 -> 367875 | I6: =$B6-I5 -> 367875 | J6: =$B6-J5 -> 367875
A7: Visitas de terceros | B7: ='Línea base'!$B$8/4 -> 267500 | C7: =$B7-C5 -> 264394.87 | D7: =$B7-D5 -> 248869.24 | E7: =$B7-E5 -> 220923.09 | F7: =$B7-F5 -> 199187.2 | G7: =$B7-G5 -> 189375 | H7: =$B7-H5 -> 189375 | I7: =$B7-I5 -> 189375 | J7: =$B7-J5 -> 189375
A8: Técnicos de terceros equivalentes | B8: =Supuestos!$B$8 -> 600 | C8: =$B8-C5/(Supuestos!$B$9*Supuestos!$B$10/4) -> 593.04173 | D8: =$B8-D5/(Supuestos!$B$9*Supuestos!$B$10/4) -> 558.25039 | E8: =$B8-E5/(Supuestos!$B$9*Supuestos!$B$10/4) -> 495.62598 | F8: =$B8-F5/(Supuestos!$B$9*Supuestos!$B$10/4) -> 446.9181 | G8: =$B8-G5/(Supuestos!$B$9*Supuestos!$B$10/4) -> 424.92997 | H8: =$B8-H5/(Supuestos!$B$9*Supuestos!$B$10/4) -> 424.92997 | I8: =$B8-I5/(Supuestos!$B$9*Supuestos!$B$10/4) -> 424.92997 | J8: =$B8-J5/(Supuestos!$B$9*Supuestos!$B$10/4) -> 424.92997
A9: Técnicos propios a 7 visitas/día (sin despidos) | B9: =Supuestos!$B$7 -> 400 | C9: =$B9 -> 400 | D9: =$B9 -> 400 | E9: =$B9 -> 400 | F9: =$B9 -> 400 | G9: =$B9 -> 400 | H9: =$B9 -> 400 | I9: =$B9 -> 400 | J9: =$B9 -> 400
A10: Visitas cada 100 órdenes resueltas | B10: ='Línea base'!$B$11 -> 147.97611 | C10: =C6/(Supuestos!$B$12/4)*100 -> 146.94588 | D10: =D6/(Supuestos!$B$12/4)*100 -> 141.7947 | E10: =E6/(Supuestos!$B$12/4)*100 -> 132.52259 | F10: =F6/(Supuestos!$B$12/4)*100 -> 125.31095 | G10: =G6/(Supuestos!$B$12/4)*100 -> 122.05541 | H10: =H6/(Supuestos!$B$12/4)*100 -> 122.05541 | I10: =I6/(Supuestos!$B$12/4)*100 -> 122.05541 | J10: =J6/(Supuestos!$B$12/4)*100 -> 122.05541
A11: Órdenes resueltas por técnico y día | B11: ='Línea base'!$B$12 -> 4.7278431 | C11: =Supuestos!$B$9*100/C10 -> 4.7636587 | D11: =Supuestos!$B$9*100/D10 -> 4.9367147 | E11: =Supuestos!$B$9*100/E10 -> 5.2821182 | F11: =Supuestos!$B$9*100/F10 -> 5.586104 | G11: =Supuestos!$B$9*100/G10 -> 5.7351002 | H11: =Supuestos!$B$9*100/H10 -> 5.7351002 | I11: =Supuestos!$B$9*100/I10 -> 5.7351002 | J11: =Supuestos!$B$9*100/J10 -> 5.7351002
A13: Financiero (USD M)
A14: Factura de terceros | B14: ='Línea base'!$B$10/4 -> 8.56 | C14: =C7*Supuestos!$B$14/10^6 -> 8.4606359 | D14: =D7*Supuestos!$B$14/10^6 -> 7.9638156 | E14: =E7*Supuestos!$B$14/10^6 -> 7.069539 | F14: =F7*Supuestos!$B$14/10^6 -> 6.3739905 | G14: =G7*Supuestos!$B$14/10^6 -> 6.06 | H14: =H7*Supuestos!$B$14/10^6 -> 6.06 | I14: =I7*Supuestos!$B$14/10^6 -> 6.06 | J14: =J7*Supuestos!$B$14/10^6 -> 6.06 | K14: =SUM(C14:J14) -> 54.107981
A15: Beneficio bruto incremental | C15: =Beneficios!$B$27 -> 0.1 | D15: =Beneficios!$C$27 -> 0.6 | E15: =Beneficios!$D$27 -> 1.5 | F15: =Beneficios!$E$27 -> 2.2 | G15: =Beneficios!$F$27 -> 2.516 | H15: =Beneficios!$G$27 -> 2.516 | I15: =Beneficios!$H$27 -> 2.516 | J15: =Beneficios!$I$27 -> 2.516 | K15: =SUM(C15:J15) -> 14.464
A16: de lo cual ingreso: bonificaciones evitadas | C16: =C15*Beneficios!$D$10/Beneficios!$D$11 -> 0.0036168521 | D16: =D15*Beneficios!$D$10/Beneficios!$D$11 -> 0.021701113 | E16: =E15*Beneficios!$D$10/Beneficios!$D$11 -> 0.054252782 | F16: =F15*Beneficios!$D$10/Beneficios!$D$11 -> 0.079570747 | G16: =G15*Beneficios!$D$10/Beneficios!$D$11 -> 0.091 | H16: =H15*Beneficios!$D$10/Beneficios!$D$11 -> 0.091 | I16: =I15*Beneficios!$D$10/Beneficios!$D$11 -> 0.091 | J16: =J15*Beneficios!$D$10/Beneficios!$D$11 -> 0.091 | K16: =SUM(C16:J16) -> 0.52314149
A17: de lo cual ahorro neto en costo de campo | C17: =C15-C16 -> 0.096383148 | D17: =D15-D16 -> 0.57829889 | E17: =E15-E16 -> 1.4457472 | F17: =F15-F16 -> 2.1204293 | G17: =G15-G16 -> 2.425 | H17: =H15-H16 -> 2.425 | I17: =I15-I16 -> 2.425 | J17: =J15-J16 -> 2.425 | K17: =SUM(C17:J17) -> 13.940859
A18: Opex de la IA | C18: =-Inversión!$B$31 -> -0.1 | D18: =-Inversión!$C$31 -> -0.2 | E18: =-Inversión!$D$31 -> -0.22 | F18: =-Inversión!$E$31 -> -0.28 | G18: =Beneficios!$D$12/4 -> -0.325 | H18: =Beneficios!$D$12/4 -> -0.325 | I18: =Beneficios!$D$12/4 -> -0.325 | J18: =Beneficios!$D$12/4 -> -0.325 | K18: =SUM(C18:J18) -> -2.1
A19: Beneficio neto incremental | C19: =C15+C18 -> 0 | D19: =D15+D18 -> 0.4 | E19: =E15+E18 -> 1.28 | F19: =F15+F18 -> 1.92 | G19: =G15+G18 -> 2.191 | H19: =H15+H18 -> 2.191 | I19: =I15+I18 -> 2.191 | J19: =J15+J18 -> 2.191 | K19: =SUM(C19:J19) -> 12.364
A20: Inversión | C20: =-Inversión!$B$15 -> -1.35 | D20: =-Inversión!$C$15 -> -1.94 | E20: =-Inversión!$D$15 -> -1.29 | F20: =-Inversión!$E$15 -> -0.82 | G20: =0 -> 0 | H20: =0 -> 0 | I20: =0 -> 0 | J20: =0 -> 0 | K20: =SUM(C20:J20) -> -5.4
A21: Flujo del trimestre | C21: =C19+C20 -> -1.35 | D21: =D19+D20 -> -1.54 | E21: =E19+E20 -> -0.01 | F21: =F19+F20 -> 1.1 | G21: =G19+G20 -> 2.191 | H21: =H19+H20 -> 2.191 | I21: =I19+I20 -> 2.191 | J21: =J19+J20 -> 2.191 | K21: =SUM(C21:J21) -> 6.964
A22: Flujo acumulado | C22: =C21 -> -1.35 | D22: =C22+D21 -> -2.89 | E22: =D22+E21 -> -2.9 | F22: =E22+F21 -> -1.8 | G22: =F22+G21 -> 0.391 | H22: =G22+H21 -> 2.582 | I22: =H22+I21 -> 4.773 | J22: =I22+J21 -> 6.964
A23: ROI acumulado | C23: =(SUM($C19:C19)+SUM($C20:C20))/-SUM($C20:C20) -> -1 | D23: =(SUM($C19:D19)+SUM($C20:D20))/-SUM($C20:D20) -> -0.87841945 | E23: =(SUM($C19:E19)+SUM($C20:E20))/-SUM($C20:E20) -> -0.63318777 | F23: =(SUM($C19:F19)+SUM($C20:F20))/-SUM($C20:F20) -> -0.33333333 | G23: =(SUM($C19:G19)+SUM($C20:G20))/-SUM($C20:G20) -> 0.072407407 | H23: =(SUM($C19:H19)+SUM($C20:H20))/-SUM($C20:H20) -> 0.47814815 | I23: =(SUM($C19:I19)+SUM($C20:I20))/-SUM($C20:I20) -> 0.88388889 | J23: =(SUM($C19:J19)+SUM($C20:J20))/-SUM($C20:J20) -> 1.2896296
A24: Métrica norte (USD por orden resuelta) | B24: ='Línea base'!$B$26 -> 47.279363 | C24: =(Supuestos!$B$13/4-C17-C18)*10^6/(Supuestos!$B$12/4) -> 47.291363 | D24: =(Supuestos!$B$13/4-D17-D18)*10^6/(Supuestos!$B$12/4) -> 46.024224 | E24: =(Supuestos!$B$13/4-E17-E18)*10^6/(Supuestos!$B$12/4) -> 43.212518 | F24: =(Supuestos!$B$13/4-F17-F18)*10^6/(Supuestos!$B$12/4) -> 41.173095 | G24: =(Supuestos!$B$13/4-G17-G18)*10^6/(Supuestos!$B$12/4) -> 40.311878 | H24: =(Supuestos!$B$13/4-H17-H18)*10^6/(Supuestos!$B$12/4) -> 40.311878 | I24: =(Supuestos!$B$13/4-I17-I18)*10^6/(Supuestos!$B$12/4) -> 40.311878 | J24: =(Supuestos!$B$13/4-J17-J18)*10^6/(Supuestos!$B$12/4) -> 40.311878
A26: Desde cuándo se ve el retorno
A27: Primer ahorro en la factura de terceros | B27: =INDEX($C$3:$J$3,MATCH(TRUE(),INDEX(C17:J17>0,0),0)) -> Q1 2027
A28: Primer ingreso (bonificaciones evitadas ≥ USD 0,01 M) | B28: =INDEX($C$3:$J$3,MATCH(TRUE(),INDEX(C16:J16>=0.01,0),0)) -> Q2 2027
A29: Beneficio neto positivo (beneficio > opex) | B29: =INDEX($C$3:$J$3,MATCH(TRUE(),INDEX(C19:J19>0.005,0),0)) -> Q2 2027
A30: Flujo trimestral positivo (beneficio > inversión) | B30: =INDEX($C$3:$J$3,MATCH(TRUE(),INDEX(C21:J21>0,0),0)) -> Q4 2027
A31: Payback: flujo acumulado positivo | B31: =INDEX($C$3:$J$3,MATCH(TRUE(),INDEX(C22:J22>=0,0),0)) -> Q1 2028
A32: ROI acumulado mayor a 100% | B32: =INDEX($C$3:$J$3,MATCH(TRUE(),INDEX(C23:J23>1,0),0)) -> Q4 2028
A33: Reducción de la factura de terceros a régimen | B33: =1-J14/B14 -> 0.29205607
A34: Técnicos de terceros equivalentes liberados a régimen | B34: =B8-J8 -> 175.07003
A36: Cómo se mide (certifica Control de Gestión, bajo el CFO, antes de cada gate)
A37: 1. Ahorro del trimestre = (visitas por orden de la línea base − visitas por orden del trimestre) × órdenes del trimestre × USD 32 − costo de resolución remota.
A38: 2. Grupo de control del 10%: si el control también mejora, esa mejora se descuenta.
A39: 3. Conciliación con la factura de terceros: una diferencia mayor al 10% se explica ante el comité.
A40: 4. Ocupación de la planta propia: los 400 técnicos propios siguen en 7 visitas por día.
A41: 5. ROI acumulado = (beneficio neto acumulado − inversión acumulada) / inversión acumulada.
A42: 6. No se cuentan minutos de papeleo, NPS ni horas de técnicos propios: no generan caja.

Sheet Proyección 5 años
A1: Proyección a 5 años, VAN y TIR (USD M)
A2: 2027 sale del flujo trimestral. Desde 2029 el bruto crece 2% anual (redondeado a USD 10 mil).
A4: Concepto | B4: 2027 | C4: 2028 | D4: 2029 | E4: 2030 | F4: 2031 | G4: Total 5 años
A5: Beneficio bruto | B5: =SUM('Flujo y ROI'!C15:F15) -> 4.4 | C5: =ROUND(Beneficios!$D$11,2) -> 10.06 | D5: =ROUND(C5*(1+Supuestos!$B$43),2) -> 10.26 | E5: =ROUND(D5*(1+Supuestos!$B$43),2) -> 10.47 | F5: =ROUND(E5*(1+Supuestos!$B$43),2) -> 10.68 | G5: =SUM(B5:F5) -> 45.87
A6: Opex recurrente de la IA | B6: =SUM('Flujo y ROI'!C18:F18) -> -0.8 | C6: =Beneficios!$D$12 -> -1.3 | D6: =-Supuestos!$B$46 -> -1.36 | E6: =-Supuestos!$B$47 -> -1.37 | F6: =-Supuestos!$B$48 -> -1.48 | G6: =SUM(B6:F6) -> -6.31
A7: Inversión única | B7: =-Inversión!$F$15 -> -5.4 | C7: =0 -> 0 | D7: =0 -> 0 | E7: =0 -> 0 | F7: =0 -> 0 | G7: =SUM(B7:F7) -> -5.4
A8: Reinversión (modelos y equipos) | B8: =0 -> 0 | C8: =0 -> 0 | D8: =-Supuestos!$B$49 -> -0.3 | E8: =-Supuestos!$B$50 -> -0.3 | F8: =-Supuestos!$B$51 -> -0.1 | G8: =SUM(B8:F8) -> -0.7
A9: Flujo antes de impuestos | B9: =SUM(B5:B8) -> -1.8 | C9: =SUM(C5:C8) -> 8.76 | D9: =SUM(D5:D8) -> 8.6 | E9: =SUM(E5:E8) -> 8.8 | F9: =SUM(F5:F8) -> 9.1 | G9: =SUM(B9:F9) -> 33.46
A10: Acumulado | B10: =B9 -> -1.8 | C10: =B10+C9 -> 6.96 | D10: =C10+D9 -> 15.56 | E10: =D10+E9 -> 24.36 | F10: =E10+F9 -> 33.46
A12: Impuestos (35%; inversión y reinversión amortizadas en 3 años)
A13: Beneficio operativo (bruto − opex) | B13: =B5+B6 -> 3.6 | C13: =C5+C6 -> 8.76 | D13: =D5+D6 -> 8.9 | E13: =E5+E6 -> 9.1 | F13: =F5+F6 -> 9.2 | G13: =SUM(B13:F13) -> 39.56
A14: Amortización | B14: =(-B7-B8)/Supuestos!$B$45 -> 1.8 | C14: =(-B7-B8)/Supuestos!$B$45+(-C7-C8)/Supuestos!$B$45 -> 1.8 | D14: =(-B7-B8)/Supuestos!$B$45+(-C7-C8)/Supuestos!$B$45+(-D7-D8)/Supuestos!$B$45 -> 1.9 | E14: =(-C7-C8)/Supuestos!$B$45+(-D7-D8)/Supuestos!$B$45+(-E7-E8)/Supuestos!$B$45 -> 0.2 | F14: =(-D7-D8)/Supuestos!$B$45+(-E7-E8)/Supuestos!$B$45+(-F7-F8)/Supuestos!$B$45 -> 0.23333333 | G14: =SUM(B14:F14) -> 5.9333333
A15: Base imponible | B15: =B13-B14 -> 1.8 | C15: =C13-C14 -> 6.96 | D15: =D13-D14 -> 7 | E15: =E13-E14 -> 8.9 | F15: =F13-F14 -> 8.9666667 | G15: =SUM(B15:F15) -> 33.626667
A16: Impuesto a las ganancias | B16: =-MAX(0,B15)*Supuestos!$B$44 -> -0.63 | C16: =-MAX(0,C15)*Supuestos!$B$44 -> -2.436 | D16: =-MAX(0,D15)*Supuestos!$B$44 -> -2.45 | E16: =-MAX(0,E15)*Supuestos!$B$44 -> -3.115 | F16: =-MAX(0,F15)*Supuestos!$B$44 -> -3.1383333 | G16: =SUM(B16:F16) -> -11.769333
A17: Flujo después de impuestos | B17: =B9+B16 -> -2.43 | C17: =C9+C16 -> 6.324 | D17: =D9+D16 -> 6.15 | E17: =E9+E16 -> 5.685 | F17: =F9+F16 -> 5.9616667 | G17: =SUM(B17:F17) -> 21.690667
A19: Flujos trimestrales (base del VAN y la TIR; descuento a mitad de trimestre)
A20: Concepto trimestral | B20: Q1 2027 | C20: Q2 2027 | D20: Q3 2027 | E20: Q4 2027 | F20: Q1 2028 | G20: Q2 2028 | H20: Q3 2028 | I20: Q4 2028 | J20: Q1 2029 | K20: Q2 2029 | L20: Q3 2029 | M20: Q4 2029 | N20: Q1 2030 | O20: Q2 2030 | P20: Q3 2030 | Q20: Q4 2030 | R20: Q1 2031 | S20: Q2 2031 | T20: Q3 2031 | U20: Q4 2031
A21: Tiempo (años, mitad de trimestre) | B21: =(0+0.5)/4 -> 0.125 | C21: =(1+0.5)/4 -> 0.375 | D21: =(2+0.5)/4 -> 0.625 | E21: =(3+0.5)/4 -> 0.875 | F21: =(4+0.5)/4 -> 1.125 | G21: =(5+0.5)/4 -> 1.375 | H21: =(6+0.5)/4 -> 1.625 | I21: =(7+0.5)/4 -> 1.875 | J21: =(8+0.5)/4 -> 2.125 | K21: =(9+0.5)/4 -> 2.375 | L21: =(10+0.5)/4 -> 2.625 | M21: =(11+0.5)/4 -> 2.875 | N21: =(12+0.5)/4 -> 3.125 | O21: =(13+0.5)/4 -> 3.375 | P21: =(14+0.5)/4 -> 3.625 | Q21: =(15+0.5)/4 -> 3.875 | R21: =(16+0.5)/4 -> 4.125 | S21: =(17+0.5)/4 -> 4.375 | T21: =(18+0.5)/4 -> 4.625 | U21: =(19+0.5)/4 -> 4.875
A22: Beneficio bruto | B22: =Beneficios!$B$27 -> 0.1 | C22: =Beneficios!$C$27 -> 0.6 | D22: =Beneficios!$D$27 -> 1.5 | E22: =Beneficios!$E$27 -> 2.2 | F22: =C$5/4 -> 2.515 | G22: =C$5/4 -> 2.515 | H22: =C$5/4 -> 2.515 | I22: =C$5/4 -> 2.515 | J22: =D$5/4 -> 2.565 | K22: =D$5/4 -> 2.565 | L22: =D$5/4 -> 2.565 | M22: =D$5/4 -> 2.565 | N22: =E$5/4 -> 2.6175 | O22: =E$5/4 -> 2.6175 | P22: =E$5/4 -> 2.6175 | Q22: =E$5/4 -> 2.6175 | R22: =F$5/4 -> 2.67 | S22: =F$5/4 -> 2.67 | T22: =F$5/4 -> 2.67 | U22: =F$5/4 -> 2.67
A23: Opex de la IA | B23: =-Inversión!$B$31 -> -0.1 | C23: =-Inversión!$C$31 -> -0.2 | D23: =-Inversión!$D$31 -> -0.22 | E23: =-Inversión!$E$31 -> -0.28 | F23: =C$6/4 -> -0.325 | G23: =C$6/4 -> -0.325 | H23: =C$6/4 -> -0.325 | I23: =C$6/4 -> -0.325 | J23: =D$6/4 -> -0.34 | K23: =D$6/4 -> -0.34 | L23: =D$6/4 -> -0.34 | M23: =D$6/4 -> -0.34 | N23: =E$6/4 -> -0.3425 | O23: =E$6/4 -> -0.3425 | P23: =E$6/4 -> -0.3425 | Q23: =E$6/4 -> -0.3425 | R23: =F$6/4 -> -0.37 | S23: =F$6/4 -> -0.37 | T23: =F$6/4 -> -0.37 | U23: =F$6/4 -> -0.37
A24: Inversión y reinversión | B24: =-Inversión!$B$15 -> -1.35 | C24: =-Inversión!$C$15 -> -1.94 | D24: =-Inversión!$D$15 -> -1.29 | E24: =-Inversión!$E$15 -> -0.82 | F24: =C$8/4 -> 0 | G24: =C$8/4 -> 0 | H24: =C$8/4 -> 0 | I24: =C$8/4 -> 0 | J24: =D$8/4 -> -0.075 | K24: =D$8/4 -> -0.075 | L24: =D$8/4 -> -0.075 | M24: =D$8/4 -> -0.075 | N24: =E$8/4 -> -0.075 | O24: =E$8/4 -> -0.075 | P24: =E$8/4 -> -0.075 | Q24: =E$8/4 -> -0.075 | R24: =F$8/4 -> -0.025 | S24: =F$8/4 -> -0.025 | T24: =F$8/4 -> -0.025 | U24: =F$8/4 -> -0.025
A25: Flujo antes de impuestos | B25: =B22+B23+B24 -> -1.35 | C25: =C22+C23+C24 -> -1.54 | D25: =D22+D23+D24 -> -0.01 | E25: =E22+E23+E24 -> 1.1 | F25: =F22+F23+F24 -> 2.19 | G25: =G22+G23+G24 -> 2.19 | H25: =H22+H23+H24 -> 2.19 | I25: =I22+I23+I24 -> 2.19 | ... U25: =U22+U23+U24 -> 2.275
A26: Flujo después de impuestos | B26: =B25+B$16/4 -> -1.5075 | C26: =C25+B$16/4 -> -1.6975 | D26: =D25+B$16/4 -> -0.1675 | E26: =E25+B$16/4 -> 0.9425 | F26: =F25+C$16/4 -> 1.581 | G26: =G25+C$16/4 -> 1.581 | H26: =H25+C$16/4 -> 1.581 | I26: =I25+C$16/4 -> 1.581 | J26: =J25+D$16/4 -> 1.5375 | K26: =K25+D$16/4 -> 1.5375 | L26: =L25+D$16/4 -> 1.5375 | M26: =M25+D$16/4 -> 1.5375 | N26: =N25+E$16/4 -> 1.42125 | O26: =O25+E$16/4 -> 1.42125 | P26: =P25+E$16/4 -> 1.42125 | Q26: =Q25+E$16/4 -> 1.42125 | R26: =R25+F$16/4 -> 1.4904167 | S26: =S25+F$16/4 -> 1.4904167 | T26: =T25+F$16/4 -> 1.4904167 | U26: =U25+F$16/4 -> 1.4904167
A27: Factor de descuento (WACC 16%) | B27: =1/(1+Supuestos!$B$42)^B21 -> 0.98161854 | C27: =1/(1+Supuestos!$B$42)^C21 -> 0.94586304 | D27: =1/(1+Supuestos!$B$42)^D21 -> 0.91140993 | E27: =1/(1+Supuestos!$B$42)^E21 -> 0.87821178 | F27: =1/(1+Supuestos!$B$42)^F21 -> 0.84622288 | G27: =1/(1+Supuestos!$B$42)^G21 -> 0.81539917 | H27: =1/(1+Supuestos!$B$42)^H21 -> 0.78569822 | I27: =1/(1+Supuestos!$B$42)^I21 -> 0.75707912 | ... U27: =1/(1+Supuestos!$B$42)^U21 -> 0.48502855
A28: Factor de descuento (WACC 20%, sensibilidad) | B28: =1/(1+0.2)^B21 -> 0.97746754 | C28: =1/(1+0.2)^C21 -> 0.93391432 | D28: =1/(1+0.2)^D21 -> 0.8923017 | E28: =1/(1+0.2)^E21 -> 0.85254323 | F28: =1/(1+0.2)^F21 -> 0.81455628 | G28: =1/(1+0.2)^G21 -> 0.77826193 | H28: =1/(1+0.2)^H21 -> 0.74358475 | I28: =1/(1+0.2)^I21 -> 0.71045269 | ... U28: =1/(1+0.2)^U21 -> 0.4111416
A29: Pesimista: flujo antes de impuestos | B29: =B22*Supuestos!$B$54+(B23+B24)*Supuestos!$B$55 -> -1.69 | C29: =C22*Supuestos!$B$54+(C23+C24)*Supuestos!$B$55 -> -2.268 | D29: =D22*Supuestos!$B$54+(D23+D24)*Supuestos!$B$55 -> -1.062 | E29: =E22*Supuestos!$B$54+(E23+E24)*Supuestos!$B$55 -> -0.22 | F29: =F22*Supuestos!$B$54+(F23+F24)*Supuestos!$B$55 -> 0.8675 | G29: =G22*Supuestos!$B$54+(G23+G24)*Supuestos!$B$55 -> 0.8675 | H29: =H22*Supuestos!$B$54+(H23+H24)*Supuestos!$B$55 -> 0.8675 | I29: =I22*Supuestos!$B$54+(I23+I24)*Supuestos!$B$55 -> 0.8675 | ... U29: =U22*Supuestos!$B$54+(U23+U24)*Supuestos!$B$55 -> 0.861
A30: Optimista: flujo antes de impuestos | B30: =B22*Supuestos!$B$58+(B23+B24)*Supuestos!$B$59 -> -1.32 | C30: =C22*Supuestos!$B$58+(C23+C24)*Supuestos!$B$59 -> -1.36 | D30: =D22*Supuestos!$B$58+(D23+D24)*Supuestos!$B$59 -> 0.44 | E30: =E22*Supuestos!$B$58+(E23+E24)*Supuestos!$B$59 -> 1.76 | F30: =F22*Supuestos!$B$58+(F23+F24)*Supuestos!$B$59 -> 2.9445 | G30: =G22*Supuestos!$B$58+(G23+G24)*Supuestos!$B$59 -> 2.9445 | H30: =H22*Supuestos!$B$58+(H23+H24)*Supuestos!$B$59 -> 2.9445 | I30: =I22*Supuestos!$B$58+(I23+I24)*Supuestos!$B$59 -> 2.9445 | ... U30: =U22*Supuestos!$B$58+(U23+U24)*Supuestos!$B$59 -> 3.076
A31: Pesimista: acumulado | B31: =B29 -> -1.69 | C31: =B31+C29 -> -3.958 | D31: =C31+D29 -> -5.02 | E31: =D31+E29 -> -5.24 | F31: =E31+F29 -> -4.3725 | G31: =F31+G29 -> -3.505 | H31: =G31+H29 -> -2.6375 | I31: =H31+I29 -> -1.77 | J31: =I31+J29 -> -0.9855 | ... U31: =T31+U29 -> 8.043
A32: Base: acumulado | B32: =B25 -> -1.35 | C32: =B32+C25 -> -2.89 | D32: =C32+D25 -> -2.9 | E32: =D32+E25 -> -1.8 | F32: =E32+F25 -> 0.39 | G32: =F32+G25 -> 2.58 | H32: =G32+H25 -> 4.77 | I32: =H32+I25 -> 6.96 | J32: =I32+J25 -> 9.11 | ... U32: =T32+U25 -> 33.46
A33: Optimista: acumulado | B33: =B30 -> -1.32 | C33: =B33+C30 -> -2.68 | D33: =C33+D30 -> -2.24 | E33: =D33+E30 -> -0.48 | F33: =E33+F30 -> 2.4645 | G33: =F33+G30 -> 5.409 | H33: =G33+H30 -> 8.3535 | I33: =H33+I30 -> 11.298 | J33: =I33+J30 -> 14.2175 | ... U33: =T33+U30 -> 47.221
A35: Indicadores
A36: Indicador | B36: Antes de impuestos | C36: Después de impuestos
A37: VAN 5 años (WACC 16%, USD M) | B37: =SUMPRODUCT($B$25:$U$25,$B$27:$U$27) -> 21.041388 | C37: =SUMPRODUCT($B$26:$U$26,$B$27:$U$27) -> 13.347289
A38: TIR anual | B38: =(1+IRR($B$25:$U$25))^4-1 -> 2.7561358 | C38: =(1+IRR($B$26:$U$26))^4-1 -> 1.7498272
A39: Payback (primer trimestre con acumulado ≥ 0) | B39: =INDEX($B$20:$U$20,MATCH(TRUE(),INDEX($B$32:$U$32>=0,0),0)) -> Q1 2028
A40: Neto a 24 meses (USD M) | B40: =SUM($B$25:$I$25) -> 6.96
A41: Beneficio neto anual a régimen (USD M) | B41: =Beneficios!$D$13 -> 8.764
A42: Run-rate neto al salir de Q4 2027 (USD M/año) | B42: =Beneficios!$D$13 -> 8.764
A43: La TIR es alta porque USD 5,4 M atacan USD 57 M de gasto anual; el número a defender es el VAN.

Sheet Escenarios
A1: Escenarios: probabilidad, resultado, gatillo y decisión preacordada (USD M)
A2: El pesimista supone que se gasta todo; si el gate de Q2 frena el tramo 2, la exposición baja a USD 2,11 M.
A4: Indicador | B4: Pesimista | C4: Base | D4: Optimista | E4: Esperado (ponderado)
A5: Probabilidad | B5: =Supuestos!$B$53 -> 0.25 | C5: =Supuestos!$B$56 -> 0.5 | D5: =Supuestos!$B$57 -> 0.25 | E5: =SUM(B5:D5) -> 1
A6: Supuesto | B6: Mitad del beneficio bruto; +20% en inversión y opex | C6: Plan del anexo B | D6: Beneficio bruto +30%
A7: Neto a régimen (USD M/año) | B7: =ROUND(Beneficios!$D$11,2)*Supuestos!$B$54+Beneficios!$D$12*Supuestos!$B$55 -> 3.47 | C7: =Beneficios!$D$13 -> 8.764 | D7: =ROUND(Beneficios!$D$11,2)*Supuestos!$B$58+Beneficios!$D$12*Supuestos!$B$59 -> 11.778 | E7: =SUMPRODUCT($B$5:$D$5,B7:D7) -> 8.194
A8: Neto a 24 meses | B8: =SUM('Proyección 5 años'!$B$29:$I$29) -> -1.77 | C8: =SUM('Proyección 5 años'!$B$25:$I$25) -> 6.96 | D8: =SUM('Proyección 5 años'!$B$30:$I$30) -> 11.298 | E8: =SUMPRODUCT($B$5:$D$5,B8:D8) -> 5.862
A9: VAN 5 años (WACC 16%) | B9: =SUMPRODUCT('Proyección 5 años'!$B$29:$U$29,'Proyección 5 años'!$B$27:$U$27) -> 3.6727882 | C9: =SUMPRODUCT('Proyección 5 años'!$B$25:$U$25,'Proyección 5 años'!$B$27:$U$27) -> 21.041388 | D9: =SUMPRODUCT('Proyección 5 años'!$B$30:$U$30,'Proyección 5 años'!$B$27:$U$27) -> 30.28862 | E9: =SUMPRODUCT($B$5:$D$5,B9:D9) -> 19.011046
A10: TIR anual | B10: =(1+IRR('Proyección 5 años'!$B$29:$U$29))^4-1 -> 0.47800245 | C10: =(1+IRR('Proyección 5 años'!$B$25:$U$25))^4-1 -> 2.7561358 | D10: =(1+IRR('Proyección 5 años'!$B$30:$U$30))^4-1 -> 4.5214373
A11: Payback | B11: =INDEX('Proyección 5 años'!$B$20:$U$20,MATCH(TRUE(),INDEX('Proyección 5 años'!$B$31:$U$31>=0,0),0)) -> Q3 2029 | C11: =INDEX('Proyección 5 años'!$B$20:$U$20,MATCH(TRUE(),INDEX('Proyección 5 años'!$B$32:$U$32>=0,0),0)) -> Q1 2028 | D11: =INDEX('Proyección 5 años'!$B$20:$U$20,MATCH(TRUE(),INDEX('Proyección 5 años'!$B$33:$U$33>=0,0),0)) -> Q1 2028
A12: Gatillo cuantitativo | B12: En Q2: triage < 20%, re-reclamo a distancia > 1,1 × control, o sobrecosto > 20% | C12: Indicadores dentro de ±15% de la rampa planificada | D12: En Q3: triage > 50% de los casos que atiende y first-time fix ≥ 82%
A13: Decisión preacordada | B13: No liberar el tramo 2 completo; concentrar en triage y aviso proactivo; revisar en Q3 | C13: Seguir el roadmap; sumar contratistas a la app en 2028 | D13: Adelantar a Q4 2027 el piloto de mantenimiento predictivo y la predicción de repuestos
A14: Quién decide | B14: Comité de IA; aprueban CEO y CFO | C14: Comité de IA | D14: Comité de IA; aprueba el CEO
A16: Costo de esperar
A17: Beneficio esperado a régimen (USD M/año) | B17: =E7 -> 8.194
A18: Costo de cada mes de demora (USD M) | B18: =B17/12 -> 0.68283333
A19: Costo de un trimestre de demora (USD M, 0,7 × 3) | B19: =ROUND(B18,1)*3 -> 2.1
A20: Pérdida actual mientras no se decide (USD M/mes) | B20: ='Línea base'!$B$20 -> 2.1342

Sheet Sensibilidad
A1: Sensibilidad: neto a régimen, neto a 24 meses y VAN (USD M)
A2: Los cambios de beneficio son lineales: VAN = k × VP(beneficio) − VP(costos), con k = (bruto + Δ) / bruto.
A4: Si cambia… | B4: Δ beneficio bruto (USD M/año) | C4: Neto a régimen (USD M/año) | D4: Neto 24 meses | E4: VAN 5 años
A5: Caso base | B5: =0 -> 0 | C5: =ROUND(Beneficios!$D$11,2)+B5+Beneficios!$D$12 -> 8.76 | D5: =((ROUND(Beneficios!$D$11,2)+B5)/ROUND(Beneficios!$D$11,2))*SUM('Proyección 5 años'!$B$22:$I$22)+SUM('Proyección 5 años'!$B$23:$I$23)+SUM('Proyección 5 años'!$B$24:$I$24) -> 6.96 | E5: =((ROUND(Beneficios!$D$11,2)+B5)/ROUND(Beneficios!$D$11,2))*SUMPRODUCT('Proyección 5 años'!$B$22:$U$22,'Proyección 5 años'!$B$27:$U$27)+SUMPRODUCT('Proyección 5 años'!$B$23:$U$23,'Proyección 5 años'!$B$27:$U$27)+SUMPRODUCT('Proyección 5 años'!$B$24:$U$24,'Proyección 5 años'!$B$27:$U$27) -> 21.041388
A6: Triage resuelve 15% de las órdenes (no 10%) | B6: =Beneficios!$D$4*0.5 -> 1.77 | C6: =ROUND(Beneficios!$D$11,2)+B6+Beneficios!$D$12 -> 10.53 | D6: =((ROUND(Beneficios!$D$11,2)+B6)/ROUND(Beneficios!$D$11,2))*SUM('Proyección 5 años'!$B$22:$I$22)+SUM('Proyección 5 años'!$B$23:$I$23)+SUM('Proyección 5 años'!$B$24:$I$24) -> 9.5041551 | E6: =((ROUND(Beneficios!$D$11,2)+B6)/ROUND(Beneficios!$D$11,2))*SUMPRODUCT('Proyección 5 años'!$B$22:$U$22,'Proyección 5 años'!$B$27:$U$27)+SUMPRODUCT('Proyección 5 años'!$B$23:$U$23,'Proyección 5 años'!$B$27:$U$27)+SUMPRODUCT('Proyección 5 años'!$B$24:$U$24,'Proyección 5 años'!$B$27:$U$27) -> 26.464715
A7: Triage resuelve 5% de las órdenes | B7: =-Beneficios!$D$4*0.5 -> -1.77 | C7: =ROUND(Beneficios!$D$11,2)+B7+Beneficios!$D$12 -> 6.99 | D7: =((ROUND(Beneficios!$D$11,2)+B7)/ROUND(Beneficios!$D$11,2))*SUM('Proyección 5 años'!$B$22:$I$22)+SUM('Proyección 5 años'!$B$23:$I$23)+SUM('Proyección 5 años'!$B$24:$I$24) -> 4.4158449 | E7: =((ROUND(Beneficios!$D$11,2)+B7)/ROUND(Beneficios!$D$11,2))*SUMPRODUCT('Proyección 5 años'!$B$22:$U$22,'Proyección 5 años'!$B$27:$U$27)+SUMPRODUCT('Proyección 5 años'!$B$23:$U$23,'Proyección 5 años'!$B$27:$U$27)+SUMPRODUCT('Proyección 5 años'!$B$24:$U$24,'Proyección 5 años'!$B$27:$U$27) -> 15.61806
A8: First-time fix llega a 78% (no 82%) | B8: =-Beneficios!$D$6*(0.82-0.78)/(Supuestos!$B$32-Supuestos!$B$31) -> -2.1028571 | C8: =ROUND(Beneficios!$D$11,2)+B8+Beneficios!$D$12 -> 6.6571429 | D8: =((ROUND(Beneficios!$D$11,2)+B8)/ROUND(Beneficios!$D$11,2))*SUM('Proyección 5 años'!$B$22:$I$22)+SUM('Proyección 5 años'!$B$23:$I$23)+SUM('Proyección 5 años'!$B$24:$I$24) -> 3.9374041 | E8: =((ROUND(Beneficios!$D$11,2)+B8)/ROUND(Beneficios!$D$11,2))*SUMPRODUCT('Proyección 5 años'!$B$22:$U$22,'Proyección 5 años'!$B$27:$U$27)+SUMPRODUCT('Proyección 5 años'!$B$23:$U$23,'Proyección 5 años'!$B$27:$U$27)+SUMPRODUCT('Proyección 5 años'!$B$24:$U$24,'Proyección 5 años'!$B$27:$U$27) -> 14.598177
A9: Visitas fallidas bajan a 6% (no 5%) | B9: =-Beneficios!$D$5*(0.06-Supuestos!$B$30)/(Supuestos!$B$29-Supuestos!$B$30) -> -0.57066667 | C9: =ROUND(Beneficios!$D$11,2)+B9+Beneficios!$D$12 -> 8.1893333 | D9: =((ROUND(Beneficios!$D$11,2)+B9)/ROUND(Beneficios!$D$11,2))*SUM('Proyección 5 años'!$B$22:$I$22)+SUM('Proyección 5 años'!$B$23:$I$23)+SUM('Proyección 5 años'!$B$24:$I$24) -> 6.1397376 | E9: =((ROUND(Beneficios!$D$11,2)+B9)/ROUND(Beneficios!$D$11,2))*SUMPRODUCT('Proyección 5 años'!$B$22:$U$22,'Proyección 5 años'!$B$27:$U$27)+SUMPRODUCT('Proyección 5 años'!$B$23:$U$23,'Proyección 5 años'!$B$27:$U$27)+SUMPRODUCT('Proyección 5 años'!$B$24:$U$24,'Proyección 5 años'!$B$27:$U$27) -> 19.29285
A10: Costo por visita USD 28 (no 32) | B10: =-(Supuestos!$B$14-28)*Beneficios!$C$11/10^6 -> -1.25 | C10: =ROUND(Beneficios!$D$11,2)+B10+Beneficios!$D$12 -> 7.51 | D10: =((ROUND(Beneficios!$D$11,2)+B10)/ROUND(Beneficios!$D$11,2))*SUM('Proyección 5 años'!$B$22:$I$22)+SUM('Proyección 5 años'!$B$23:$I$23)+SUM('Proyección 5 años'!$B$24:$I$24) -> 5.1632803 | E10: =((ROUND(Beneficios!$D$11,2)+B10)/ROUND(Beneficios!$D$11,2))*SUMPRODUCT('Proyección 5 años'!$B$22:$U$22,'Proyección 5 años'!$B$27:$U$27)+SUMPRODUCT('Proyección 5 años'!$B$23:$U$23,'Proyección 5 años'!$B$27:$U$27)+SUMPRODUCT('Proyección 5 años'!$B$24:$U$24,'Proyección 5 años'!$B$27:$U$27) -> 17.211354
A11: WACC 20% | B11: =0 -> 0 | C11: =Beneficios!$D$13 -> 8.764 | D11: ='Proyección 5 años'!$B$40 -> 6.96 | E11: =SUMPRODUCT('Proyección 5 años'!$B$25:$U$25,'Proyección 5 años'!$B$28:$U$28) -> 18.968888
A12: Inversión y reinversión +30% | B12: =0 -> 0 | C12: =Beneficios!$D$13 -> 8.764 | D12: =SUM('Proyección 5 años'!$B$22:$I$22)+SUM('Proyección 5 años'!$B$23:$I$23)+1.3*SUM('Proyección 5 años'!$B$24:$I$24) -> 5.34 | E12: =SUMPRODUCT('Proyección 5 años'!$B$22:$U$22,'Proyección 5 años'!$B$27:$U$27)+SUMPRODUCT('Proyección 5 años'!$B$23:$U$23,'Proyección 5 años'!$B$27:$U$27)+1.3*SUMPRODUCT('Proyección 5 años'!$B$24:$U$24,'Proyección 5 años'!$B$27:$U$27) -> 19.393451
A14: Las dos variables que mueven el caso son el first-time fix y el triage: por eso el gate de Q2 mide triage y adopción, y el gate de Q3, first-time fix.

Sheet KPIs
A1: Métrica norte, KPIs y guardas: línea base vs. meta a régimen
A3: Indicador | B3: Línea base | C3: Meta a régimen | D3: Cómo se mide
A4: MÉTRICA NORTE: costo de campo por orden resuelta (USD) | B4: ='Línea base'!$B$26 -> 47.279363 | C4: =Beneficios!$D$18 -> 40.311878 | D4: Costo de campo + opex IA / órdenes resueltas
A5: Visitas cada 100 órdenes resueltas | B5: ='Línea base'!$B$11 -> 147.97611 | C5: ='Flujo y ROI'!J10 -> 122.05541 | D5: FSM
A6: Órdenes resueltas sin visita (contención del triage) | B6: 0 | C6: =Supuestos!$B$28 -> 0.1 | D6: Tratados vs. grupo de control
A7: First-time fix en reparaciones | B7: =Supuestos!$B$31 -> 0.75 | C7: =Supuestos!$B$32 -> 0.82 | D7: Sin revisita a 30 días
A8: Visitas fallidas | B8: =Supuestos!$B$29 -> 0.08 | C8: =Supuestos!$B$30 -> 0.05 | D8: FSM
A9: Factura de terceros (USD M/año) | B9: ='Línea base'!$B$10 -> 34.24 | C9: ='Flujo y ROI'!J14*4 -> 24.24 | D9: Facturas de contratistas
A10: Técnicos de terceros equivalentes | B10: =Supuestos!$B$8 -> 600 | C10: ='Flujo y ROI'!J8 -> 424.92997 | D10: Visitas de terceros / (7 × 255)
A11: Técnicos propios (sin despidos) | B11: =Supuestos!$B$7 -> 400 | C11: =Supuestos!$B$7 -> 400 | D11: Ocupación: 7 visitas por día
A12: RPU neto de campo (USD/abonado/mes) | B12: ='Línea base'!$B$29 -> 18.963542 | C12: =Beneficios!$D$20 -> 19.42 | D12: ARPU − costo de campo − bonificaciones
A13: Tiempo administrativo por técnico (min/día) | B13: 60 | C13: 35 | D13: Guarda; no se cuenta como beneficio
A15: Gate de Q2: libera el tramo 2 solo si se cumplen las cinco condiciones (contra grupo de control)
A16: 1. Volumen: el triage resuelve sin visita ≥ 20% de los reclamos que atiende.
A17: 2. Calidad: re-reclamo a 7 días de los casos resueltos a distancia ≤ 1,1 × el de los casos con visita del control.
A18: 3. Experiencia: NPS post-triage ≥ 90% del NPS post-visita del grupo de control.
A19: 4. Adopción: uso del copiloto ≥ 60% de las órdenes elegibles en la zona piloto.
A20: 5. Costo: tramo 1 sin sobrecosto mayor al 20%; cero incidentes de privacidad graves.
